Workbook
Name Slicer_Income_Level1: #N/A
Name Slicer_Region: #N/A

Sheet Dashboard

Sheet 4A. Figure A
A2: A. A column chart showing the average of the indicator across the years

Sheet 4B. Figure B 
A2: B. A bar chart across regions, showing the average primary school enrollment in 2024

Sheet 4C. Figure C 
A2: C. Clustured Column for hypothetical indicator

Sheet Back End>>

Sheet Pivot tables
D2: Figure 4A
A3: Row Labels | B3: Average of 2024 | C3: Average of 2023 | D3: Average of 2022 | E3: Average of 2021
A4: High income | B4: 99.233338 | C4: 100.97786 | D4: 100.18914 | E4: 100.34289
A5: Low income | B5: 110.01349 | C5: 101.40255 | D5: 105.68036 | E5: 107.04119
A6: Lower middle income | B6: 99.021003 | C6: 98.791341 | D6: 99.451075 | E6: 98.449858
A7: Upper middle income | B7: 100.35202 | C7: 99.952684 | D7: 100.99849 | E7: 100.97321
A8: Grand Total | B8: 100.92416 | C8: 100.18622 | D8: 100.71362 | E8: 100.54284
D11: Figure 4B
A13: Income Level | B13: (All)
A15: Row Labels | B15: Average of 2024
A16: East Asia & Pacific | B16: 98.762839
A17: Europe & Central Asia | B17: 100.87349
A18: Latin America & Caribbean | B18: 97.211229
A19: Middle East, North Africa, Afghanistan & Pakistan | B19: 97.402734
A20: North America
A21: South Asia | B21: 113.24585
A22: Sub-Saharan Africa | B22: 104.69098
A23: Grand Total | B23: 100.92416
D25: Figure 4C
B31: Column Labels
A32: Values | B32: A | C32: B | D32: C | E32: Grand Total
A33: Average of 2024 | B33: 100.12322 | C33: 103.45848 | D33: 99.270865 | E33: 100.92416
A34: Average of 2023 | B34: 100.86288 | C34: 99.274303 | D34: 100.48144 | E34: 100.18622
A35: Average of 2022 | B35: 100.73983 | C35: 100.92852 | D35: 100.45728 | E35: 100.71362

Sheet Pivot fig 4A
A3: Row Labels | B3: Average of 2021 | C3: Average of 2022 | D3: Average of 2023 | E3: Average of 2024
A4: High income | B4: 100.34289 | C4: 100.18914 | D4: 100.97786 | E4: 99.233338
A5: Low income | B5: 107.04119 | C5: 105.68036 | D5: 101.40255 | E5: 110.01349
A6: Lower middle income | B6: 98.449858 | C6: 99.451075 | D6: 98.791341 | E6: 99.021003
A7: Upper middle income | B7: 100.97321 | C7: 100.99849 | D7: 99.952684 | E7: 100.35202
A8: Grand Total | B8: 100.54284 | C8: 100.71362 | D8: 100.18622 | E8: 100.92416

Sheet Pivot 4B
A3: Row Labels | B3: Average of 2024
A4: Latin America & Caribbean | B4: 97.211229
A5: Middle East, North Africa, Afghanistan & Pakistan | B5: 97.402734
A6: East Asia & Pacific | B6: 98.762839
A7: Europe & Central Asia | B7: 100.87349
A8: Sub-Saharan Africa | B8: 104.69098
A9: South Asia | B9: 113.24585
A10: Grand Total | B10: 100.92416

Sheet Pivot 4C
B3: Column Labels
A4: Values | B4: A | C4: B | D4: C | E4: Grand Total
A5: Average of 2022 | B5: 100.73983 | C5: 100.92852 | D5: 100.45728 | E5: 100.71362
A6: Average of 2023 | B6: 100.86288 | C6: 99.274303 | D6: 100.48144 | E6: 100.18622
A7: Average of 2024 | B7: 100.12322 | C7: 103.45848 | D7: 99.270865 | E7: 100.92416

Sheet Combined Data
A1: Country Name | B1: 2020 | C1: 2021 | D1: 2022 | E1: 2023 | F1: 2024 | G1: Income Level | H1: Region | I1: Hypothetical Metric
A2: Afghanistan | G2: =VLOOKUP('Combined Data'!A:A,Table13[#All],4, FALSE) -> Low income | H2: =VLOOKUP('Combined Data'!A:A,Table13[],3, FALSE) -> Middle East, North Africa, Afghanistan & Pakistan | I2: A
A3: Albania | B3: 100.02097 | C3: 97.107504 | D3: 96.37123 | E3: 93.713812 | F3: 111.51165 | G3: =VLOOKUP('Combined Data'!A:A,Table13[#All],4, FALSE) -> Upper middle income | H3: =VLOOKUP('Combined Data'!A:A,Table13[],3, FALSE) -> Europe & Central Asia | I3: B
A4: Algeria | B4: 108.53194 | C4: 104.73976 | D4: 105.74715 | E4: 105.84075 | F4: 106.36889 | G4: =VLOOKUP('Combined Data'!A:A,Table13[#All],4, FALSE) -> Upper middle income | H4: =VLOOKUP('Combined Data'!A:A,Table13[],3, FALSE) -> Middle East, North Africa, Afghanistan & Pakistan | I4: C
A5: American Samoa | G5: =VLOOKUP('Combined Data'!A:A,Table13[#All],4, FALSE) -> High income | H5: =VLOOKUP('Combined Data'!A:A,Table13[],3, FALSE) -> East Asia & Pacific | I5: A
A6: Andorra | B6: 89.427127 | C6: 89.737991 | D6: 90.465681 | E6: 97.444673 | F6: 99.857955 | G6: =VLOOKUP('Combined Data'!A:A,Table13[#All],4, FALSE) -> High income | H6: =VLOOKUP('Combined Data'!A:A,Table13[],3, FALSE) -> Europe & Central Asia | I6: B
A7: Angola | C7: 89.226609 | E7: 86.735392 | G7: =VLOOKUP('Combined Data'!A:A,Table13[#All],4, FALSE) -> Lower middle income | H7: =VLOOKUP('Combined Data'!A:A,Table13[],3, FALSE) -> Sub-Saharan Africa | I7: C
A8: Antigua and Barbuda | D8: 121.56321 | E8: 112.25541 | G8: =VLOOKUP('Combined Data'!A:A,Table13[#All],4, FALSE) -> High income | H8: =VLOOKUP('Combined Data'!A:A,Table13[],3, FALSE) -> Latin America & Caribbean | I8: A
A9: Argentina | B9: 108.50462 | C9: 108.13962 | D9: 106.75983 | E9: 102.53524 | G9: =VLOOKUP('Combined Data'!A:A,Table13[#All],4, FALSE) -> Upper middle income | H9: =VLOOKUP('Combined Data'!A:A,Table13[],3, FALSE) -> Latin America & Caribbean | I9: B
A10: Armenia | B10: 92.869262 | C10: 94.63922 | D10: 96.94543 | E10: 98.089988 | F10: 101.99055 | G10: =VLOOKUP('Combined Data'!A:A,Table13[#All],4, FALSE) -> Upper middle income | H10: =VLOOKUP('Combined Data'!A:A,Table13[],3, FALSE) -> Europe & Central Asia | I10: C
A11: Aruba | B11: 107.23534 | C11: 108.59951 | D11: 102.62073 | F11: 107.717 | G11: =VLOOKUP('Combined Data'!A:A,Table13[#All],4, FALSE) -> High income | H11: =VLOOKUP('Combined Data'!A:A,Table13[],3, FALSE) -> Latin America & Caribbean | I11: A
A12: Australia | B12: 99.901108 | C12: 99.929153 | D12: 99.132988 | E12: 99.365753 | G12: =VLOOKUP('Combined Data'!A:A,Table13[#All],4, FALSE) -> High income | H12: =VLOOKUP('Combined Data'!A:A,Table13[],3, FALSE) -> East Asia & Pacific | I12: B
A13: Austria | B13: 101.56085 | C13: 101.64412 | D13: 100.77563 | E13: 100.90287 | G13: =VLOOKUP('Combined Data'!A:A,Table13[#All],4, FALSE) -> High income | H13: =VLOOKUP('Combined Data'!A:A,Table13[],3, FALSE) -> Europe & Central Asia | I13: C
A14: Azerbaijan | B14: 98.236071 | C14: 97.7305 | D14: 99.808298 | E14: 101.9797 | F14: 105.62502 | G14: =VLOOKUP('Combined Data'!A:A,Table13[#All],4, FALSE) -> Upper middle income | H14: =VLOOKUP('Combined Data'!A:A,Table13[],3, FALSE) -> Europe & Central Asia | I14: A
A15: Bahamas, The | C15: 80.523712 | E15: 78.393193 | F15: 92.856648 | G15: =VLOOKUP('Combined Data'!A:A,Table13[#All],4, FALSE) -> High income | H15: =VLOOKUP('Combined Data'!A:A,Table13[],3, FALSE) -> Latin America & Caribbean | I15: B
A16: Bahrain | D16: 96.992729 | E16: 93.899895 | F16: 96.875248 | G16: =VLOOKUP('Combined Data'!A:A,Table13[#All],4, FALSE) -> High income | H16: =VLOOKUP('Combined Data'!A:A,Table13[],3, FALSE) -> Middle East, North Africa, Afghanistan & Pakistan | I16: C
A17: Bangladesh | B17: 110.06662 | C17: 106.33485 | D17: 107.80207 | E17: 103.11642 | F17: 106.49131 | G17: =VLOOKUP('Combined Data'!A:A,Table13[#All],4, FALSE) -> Lower middle income | H17: =VLOOKUP('Combined Data'!A:A,Table13[],3, FALSE) -> South Asia | I17: A
A18: Barbados | B18: 94.513483 | C18: 92.770903 | D18: 90.187532 | E18: 88.007569 | F18: 83.937024 | G18: =VLOOKUP('Combined Data'!A:A,Table13[#All],4, FALSE) -> High income | H18: =VLOOKUP('Combined Data'!A:A,Table13[],3, FALSE) -> Latin America & Caribbean | I18: B
A19: Belarus | B19: 95.525015 | C19: 95.526644 | D19: 95.430715 | E19: 95.218363 | F19: 96.822403 | G19: =VLOOKUP('Combined Data'!A:A,Table13[#All],4, FALSE) -> Upper middle income | H19: =VLOOKUP('Combined Data'!A:A,Table13[],3, FALSE) -> Europe & Central Asia | I19: C
A20: Belgium | B20: 102.06427 | C20: 101.82114 | D20: 102.17699 | E20: 102.10801 | G20: =VLOOKUP('Combined Data'!A:A,Table13[#All],4, FALSE) -> High income | H20: =VLOOKUP('Combined Data'!A:A,Table13[],3, FALSE) -> Europe & Central Asia | I20: A
A21: Belize | B21: 112.25143 | C21: 107.33727 | D21: 101.53137 | E21: 97.787446 | F21: 96.481925 | G21: =VLOOKUP('Combined Data'!A:A,Table13[#All],4, FALSE) -> Upper middle income | H21: =VLOOKUP('Combined Data'!A:A,Table13[],3, FALSE) -> Latin America & Caribbean | I21: B
A22: Benin | B22: 104.03317 | C22: 105.6313 | D22: 108.03624 | G22: =VLOOKUP('Combined Data'!A:A,Table13[#All],4, FALSE) -> Lower middle income | H22: =VLOOKUP('Combined Data'!A:A,Table13[],3, FALSE) -> Sub-Saharan Africa | I22: C
A23: Bermuda | E23: 92.85125 | G23: =VLOOKUP('Combined Data'!A:A,Table13[#All],4, FALSE) -> High income | H23: =VLOOKUP('Combined Data'!A:A,Table13[],3, FALSE) -> North America | I23: A
A24: Bhutan | B24: 103.82601 | C24: 105.46105 | D24: 105.26615 | E24: 106.6874 | F24: 114.88112 | G24: =VLOOKUP('Combined Data'!A:A,Table13[#All],4, FALSE) -> Lower middle income | H24: =VLOOKUP('Combined Data'!A:A,Table13[],3, FALSE) -> South Asia | I24: B
A25: Bolivia | B25: 98.236949 | C25: 98.469423 | D25: 99.196088 | E25: 98.572689 | G25: =VLOOKUP('Combined Data'!A:A,Table13[#All],4, FALSE) -> Lower middle income | H25: =VLOOKUP('Combined Data'!A:A,Table13[],3, FALSE) -> Latin America & Caribbean | I25: C
A26: Bosnia and Herzegovina | B26: 100.26393 | C26: 101.16862 | D26: 101.60451 | E26: 101.19488 | G26: =VLOOKUP('Combined Data'!A:A,Table13[#All],4, FALSE) -> Upper middle income | H26: =VLOOKUP('Combined Data'!A:A,Table13[],3, FALSE) -> Europe & Central Asia | I26: A
A27: Botswana | C27: 104.61998 | D27: 109.27326 | G27: =VLOOKUP('Combined Data'!A:A,Table13[#All],4, FALSE) -> Upper middle income | H27: =VLOOKUP('Combined Data'!A:A,Table13[],3, FALSE) -> Sub-Saharan Africa | I27: B
A28: Brazil | B28: 105.4982 | C28: 103.47168 | D28: 103.97032 | G28: =VLOOKUP('Combined Data'!A:A,Table13[#All],4, FALSE) -> Upper middle income | H28: =VLOOKUP('Combined Data'!A:A,Table13[],3, FALSE) -> Latin America & Caribbean | I28: C
A29: British Virgin Islands | B29: 86.852207 | C29: 92.687018 | D29: 73.17157 | E29: 87.316562 | F29: 72.779991 | G29: =VLOOKUP('Combined Data'!A:A,Table13[#All],4, FALSE) -> High income | H29: =VLOOKUP('Combined Data'!A:A,Table13[],3, FALSE) -> Latin America & Caribbean | I29: A
A30: Brunei Darussalam | B30: 102.70963 | C30: 101.38793 | D30: 99.134913 | E30: 96.929219 | G30: =VLOOKUP('Combined Data'!A:A,Table13[#All],4, FALSE) -> High income | H30: =VLOOKUP('Combined Data'!A:A,Table13[],3, FALSE) -> East Asia & Pacific | I30: B
A31: Bulgaria | B31: 96.543762 | C31: 95.611099 | D31: 95.888519 | E31: 95.423218 | G31: =VLOOKUP('Combined Data'!A:A,Table13[#All],4, FALSE) -> High income | H31: =VLOOKUP('Combined Data'!A:A,Table13[],3, FALSE) -> Europe & Central Asia | I31: C
A32: Burkina Faso | B32: 87.698847 | C32: 87.018335 | D32: 82.256706 | E32: 72.238595 | F32: 77.166593 | G32: =VLOOKUP('Combined Data'!A:A,Table13[#All],4, FALSE) -> Low income | H32: =VLOOKUP('Combined Data'!A:A,Table13[],3, FALSE) -> Sub-Saharan Africa | I32: A
A33: Burundi | B33: 101.66109 | G33: =VLOOKUP('Combined Data'!A:A,Table13[#All],4, FALSE) -> Low income | H33: =VLOOKUP('Combined Data'!A:A,Table13[],3, FALSE) -> Sub-Saharan Africa | I33: B
A34: Cabo Verde | B34: 103.42828 | C34: 103.02597 | D34: 102.97301 | G34: =VLOOKUP('Combined Data'!A:A,Table13[#All],4, FALSE) -> Upper middle income | H34: =VLOOKUP('Combined Data'!A:A,Table13[],3, FALSE) -> Sub-Saharan Africa | I34: C
A35: Cambodia | B35: 107.02102 | C35: 105.28248 | D35: 106.33154 | E35: 107.03901 | F35: 108.97133 | G35: =VLOOKUP('Combined Data'!A:A,Table13[#All],4, FALSE) -> Lower middle income | H35: =VLOOKUP('Combined Data'!A:A,Table13[],3, FALSE) -> East Asia & Pacific | I35: A
A36: Cameroon | C36: 110.10779 | D36: 112.49464 | E36: 114.42483 | F36: 114.40728 | G36: =VLOOKUP('Combined Data'!A:A,Table13[#All],4, FALSE) -> Lower middle income | H36: =VLOOKUP('Combined Data'!A:A,Table13[],3, FALSE) -> Sub-Saharan Africa | I36: B
A37: Canada | B37: 96.908974 | C37: 95.229622 | D37: 94.74498 | E37: 94.952339 | G37: =VLOOKUP('Combined Data'!A:A,Table13[#All],4, FALSE) -> High income | H37: =VLOOKUP('Combined Data'!A:A,Table13[],3, FALSE) -> North America | I37: C
A38: Cayman Islands | B38: 97.65238 | C38: 95.47849 | D38: 98.38567 | E38: 101.44124 | F38: 95.736691 | G38: =VLOOKUP('Combined Data'!A:A,Table13[#All],4, FALSE) -> High income | H38: =VLOOKUP('Combined Data'!A:A,Table13[],3, FALSE) -> Latin America & Caribbean | I38: A
A39: Central African Republic | G39: =VLOOKUP('Combined Data'!A:A,Table13[#All],4, FALSE) -> Low income | H39: =VLOOKUP('Combined Data'!A:A,Table13[],3, FALSE) -> Sub-Saharan Africa | I39: B
A40: Chad | C40: 86.14543 | D40: 87.034732 | E40: 88.343658 | F40: 88.464522 | G40: =VLOOKUP('Combined Data'!A:A,Table13[#All],4, FALSE) -> Low income | H40: =VLOOKUP('Combined Data'!A:A,Table13[],3, FALSE) -> Sub-Saharan Africa | I40: C
...

Sheet Region & Income Labels
A1: Economy | B1: Code | C1: Region | D1: Income group
A2: Afghanistan | B2: AFG | C2: Middle East, North Africa, Afghanistan & Pakistan | D2: Low income
A3: Albania | B3: ALB | C3: Europe & Central Asia | D3: Upper middle income
A4: Algeria | B4: DZA | C4: Middle East, North Africa, Afghanistan & Pakistan | D4: Upper middle income
A5: American Samoa | B5: ASM | C5: East Asia & Pacific | D5: High income
A6: Andorra | B6: AND | C6: Europe & Central Asia | D6: High income
A7: Angola | B7: AGO | C7: Sub-Saharan Africa | D7: Lower middle income
A8: Antigua and Barbuda | B8: ATG | C8: Latin America & Caribbean | D8: High income
A9: Argentina | B9: ARG | C9: Latin America & Caribbean | D9: Upper middle income
A10: Armenia | B10: ARM | C10: Europe & Central Asia | D10: Upper middle income
A11: Aruba | B11: ABW | C11: Latin America & Caribbean | D11: High income
A12: Australia | B12: AUS | C12: East Asia & Pacific | D12: High income
... A219: Zimbabwe | B219: ZWE | C219: Sub-Saharan Africa | D219: Lower middle income

Sheet Sheet1

Sheet Raw Data
A1: Data Source | B1: World Development Indicators
A2: Last Updated Date | B2: 46077
A4: Country Name | B4: Country Code | C4: Indicator Name | D4: Indicator Code | E4: 1960 | F4: 1961 | G4: 1962 | H4: 1963 | I4: 1964 | J4: 1965 | K4: 1966 | L4: 1967 | M4: 1968 | N4: 1969 | O4: 1970 | P4: 1971 | Q4: 1972 | R4: 1973 | S4: 1974 | T4: 1975 | U4: 1976 | V4: 1977 | W4: 1978 | X4: 1979 | Y4: 1980 | Z4: 1981 | AA4: 1982 | AB4: 1983 | AC4: 1984 | AD4: 1985 | AE4: 1986 | AF4: 1987 | AG4: 1988 | AH4: 1989 | AI4: 1990 | AJ4: 1991 | AK4: 1992 | AL4: 1993 | AM4: 1994 | AN4: 1995 | AO4: 1996 | AP4: 1997 | AQ4: 1998 | AR4: 1999 | AS4: 2000 | AT4: 2001 | AU4: 2002 | AV4: 2003 | AW4: 2004 | AX4: 2005 | AY4: 2006 | AZ4: 2007 | BA4: 2008 | BB4: 2009 | BC4: 2010 | BD4: 2011 | BE4: 2012 | BF4: 2013 | BG4: 2014 | BH4: 2015 | BI4: 2016 | BJ4: 2017 | BK4: 2018 | BL4: 2019 | BM4: 2020 | BN4: 2021 | BO4: 2022 | BP4: 2023 | BQ4: 2024 | BR4: 2025
A5: Aruba | B5: ABW | C5: School enrollment, primary (% gross) | D5: SE.PRM.ENRR | AT5: 110.34967 | AU5: 115.66945 | AV5: 115.985 | AW5: 117.21717 | AX5: 116.92904 | AY5: 117.98774 | AZ5: 116.97004 | BA5: 116.0139 | BB5: 117.52748 | BC5: 119.79584 | BD5: 106.37404 | BE5: 104.07494 | BF5: 114.98532 | BG5: 116.26199 | BH5: 115.01141 | BI5: 113.63746 | BK5: 107.98517 | BL5: 108.025 | BM5: 107.23534 | BN5: 108.59951 | BO5: 102.62073 | BQ5: 107.717
A6: Africa Eastern and Southern | B6: AFE | C6: School enrollment, primary (% gross) | D6: SE.PRM.ENRR | O6: 61.91256 | P6: 58.698681 | Q6: 59.447731 | R6: 60.60627 | S6: 64.000229 | T6: 66.272751 | U6: 67.754601 | V6: 69.59166 | W6: 70.676491 | X6: 73.460678 | Y6: 76.496948 | Z6: 78.203072 | AA6: 78.612877 | AB6: 78.332291 | AC6: 77.473579 | AD6: 75.094482 | AE6: 74.737312 | AF6: 73.19207 | AG6: 72.720177 | AH6: 74.400658 | AI6: 72.185226 | AJ6: 73.733093 | AK6: 72.365021 | AL6: 73.059418 | AM6: 73.05423 | AN6: 74.826309 | AO6: 74.57856 | AP6: 77.695381 | AQ6: 77.996162 | AR6: 76.959702 | AS6: 78.762817 | AT6: 81.484871 | AU6: 83.909821 | AV6: 87.523178 | AW6: 89.628197 | AX6: 92.893929 | AY6: 95.32148 | AZ6: 98.476608 | BA6: 102.1465 | BB6: 101.70464 | BC6: 101.0054 | BD6: 100.98524 | BE6: 101.24011 | BF6: 100.52919 | BG6: 100.93015 | BH6: 99.697533 | BI6: 100.34211 | BJ6: 101.22841 | BK6: 102.62481 | BL6: 103.61062 | BM6: 104.59194 | BN6: 103.36608 | BO6: 100.5083 | BP6: 100.85759 | BQ6: 101.30924
A7: Afghanistan | B7: AFG | C7: School enrollment, primary (% gross) | D7: SE.PRM.ENRR | O7: 31.651421 | P7: 32.539719 | Q7: 32.962872 | R7: 33.424519 | S7: 33.962811 | T7: 34.882488 | U7: 35.72823 | V7: 36.462799 | W7: 37.68219 | Y7: 43.810108 | Z7: 49.459789 | AA7: 20.136089 | AC7: 24.648439 | AD7: 25.13636 | AE7: 26.683241 | AG7: 34.07814 | AH7: 31.833389 | AI7: 30.98304 | AJ7: 31.605021 | AL7: 33.95525 | AM7: 44.788841 | AN7: 47.661442 | AQ7: 32.984329 | AR7: 26.290529 | AS7: 21.45785 | AT7: 22.13965 | AU7: 73.401314 | AV7: 95.335747 | AW7: 105.47505 | AX7: 99.503906 | AY7: 102.28487 | AZ7: 99.322899 | BA7: 104.44514 | BB7: 99.705421 | BC7: 103.4856 | BD7: 101.54208 | BE7: 106.57532 | BF7: 107.94284 | BG7: 109.82945 | BH7: 106.77355 | BI7: 106.78404 | BJ7: 106.54354 | BK7: 107.68766 | BL7: 109.07531
A8: Africa Western and Central | B8: AFW | C8: School enrollment, primary (% gross) | D8: SE.PRM.ENRR | O8: 43.072651 | P8: 44.670731 | Q8: 46.641609 | R8: 48.107719 | S8: 48.214981 | T8: 48.660488 | U8: 49.16127 | V8: 54.849289 | W8: 62.757591 | X8: 69.68129 | Y8: 72.748711 | Z8: 76.711792 | AA8: 81.487373 | AB8: 81.651688 | AC8: 80.76165 | AD8: 78.297211 | AE8: 72.141052 | AF8: 70.625893 | AG8: 68.955101 | AH8: 68.199654 | AI8: 69.515198 | AJ8: 69.671333 | AK8: 71.482918 | AL8: 73.716728 | AM8: 74.120529 | AN8: 72.753357 | AO8: 68.134697 | AP8: 71.773521 | AQ8: 74.614388 | AR8: 77.440147 | AS8: 80.579514 | AT8: 81.115791 | AU8: 82.838409 | AV8: 83.583672 | AW8: 85.46859 | AX8: 86.378983 | AY8: 87.106262 | AZ8: 84.385239 | BA8: 81.99086 | BB8: 83.719551 | BC8: 84.47847 | BD8: 87.822006 | BE8: 89.439651 | BF8: 90.58976 | BG8: 89.120697 | BH8: 87.096619 | BI8: 86.69799 | BJ8: 86.782539 | BK8: 86.652351 | BL8: 87.555557 | BM8: 88.157623 | BN8: 88.094856 | BO8: 89.501923 | BP8: 90.878036 | BQ8: 91.060989
A9: Angola | B9: AGO | C9: School enrollment, primary (% gross) | D9: SE.PRM.ENRR | P9: 62.55418 | Q9: 67.91169 | R9: 70.039902 | S9: 75.951172 | Y9: 159.81021 | Z9: 142.3615 | AA9: 133.38214 | AB9: 120.50052 | AC9: 105.08636 | AD9: 82.78463 | AE9: 89.222672 | AF9: 89.115807 | AG9: 87.219727 | AH9: 86.70517 | AI9: 81.085777 | AJ9: 73.899437 | AK9: 70.755379 | AQ9: 76.634407 | AZ9: 106.34145 | BA9: 113.29224 | BB9: 112.27895 | BC9: 113.87258 | BD9: 128.38634 | BH9: 120.58028 | BN9: 89.226609 | BP9: 86.735392
A10: Albania | B10: ALB | C10: School enrollment, primary (% gross) | D10: SE.PRM.ENRR | AU10: 110.33892 | AV10: 107.59826 | AW10: 104.13172 | AX10: 107.01614 | AY10: 105.47778 | AZ10: 103.48844 | BA10: 100.383 | BB10: 100.92374 | BC10: 99.861834 | BD10: 101.58027 | BE10: 102.06736 | BF10: 101.47495 | BG10: 105.77058 | BH10: 105.68865 | BI10: 105.32478 | BJ10: 105.41497 | BK10: 104.56802 | BL10: 102.58954 | BM10: 100.02097 | BN10: 97.107504 | BO10: 96.37123 | BP10: 93.713812 | BQ10: 111.51165
A11: Andorra | B11: AND | C11: School enrollment, primary (% gross) | D11: SE.PRM.ENRR | T11: 99.544418 | AB11: 103.19785 | AU11: 100.48924 | AV11: 102.44868 | AW11: 99.393944 | AX11: 90.05732 | AY11: 90.381813 | AZ11: 88.540001 | BA11: 87.037399 | BB11: 85.024712 | BC11: 84.944557 | BD11: 86.225731 | BE11: 83.518707 | BF11: 85.051224 | BG11: 87.026333 | BH11: 88.595745 | BI11: 91.041577 | BJ11: 90.203132 | BK11: 90.708893 | BL11: 90.323929 | BM11: 89.427127 | BN11: 89.737991 | BO11: 90.465681 | BP11: 97.444673 | BQ11: 99.857955
A12: Arab World | B12: ARB | C12: School enrollment, primary (% gross) | D12: SE.PRM.ENRR | O12: 74.427002 | P12: 69.901817 | Q12: 71.224442 | R12: 72.337883 | S12: 72.799438 | T12: 74.27697 | U12: 75.750687 | V12: 76.435722 | W12: 76.826927 | X12: 69.803329 | Y12: 79.137001 | Z12: 78.966667 | AA12: 79.61248 | AB12: 80.216377 | AC12: 80.979332 | AD12: 80.815536 | AE12: 81.515747 | AF12: 82.444794 | AG12: 83.111938 | AH12: 83.058083 | AI12: 84.048714 | AJ12: 84.737198 | AK12: 82.19648 | AL12: 82.703682 | AM12: 85.022362 | AN12: 83.728737 | AO12: 85.754333 | AP12: 86.556213 | AQ12: 86.87442 | AR12: 87.724426 | AS12: 88.103256 | AT12: 88.606911 | AU12: 89.503159 | AV12: 90.326881 | AW12: 90.533249 | AX12: 90.23719 | AY12: 91.525818 | AZ12: 91.225189 | BA12: 91.463692 | BB12: 91.379013 | BC12: 91.695457 | BD12: 90.811119 | BE12: 92.145576 | BF12: 88.686211 | BG12: 87.774139 | BH12: 87.707069 | BI12: 87.868698 | BJ12: 88.272118 | BK12: 88.761459 | BL12: 89.057938 | BM12: 89.643661 | BN12: 89.506943 | BO12: 88.10424 | BP12: 91.053581 | BQ12: 91.564072
A13: United Arab Emirates | B13: ARE | C13: School enrollment, primary (% gross) | D13: SE.PRM.ENRR | AT13: 122.86998 | AU13: 118.77543 | AV13: 117.25965 | AW13: 110.69412 | AX13: 105.71991 | AY13: 100.25807 | BK13: 105.67536 | BL13: 107.5332 | BM13: 108.0698 | BN13: 106.65283 | BO13: 107.28743 | BP13: 106.25995 | BQ13: 108.04442
A14: Argentina | B14: ARG | C14: School enrollment, primary (% gross) | D14: SE.PRM.ENRR | O14: 105.22676 | P14: 106.13772 | Q14: 105.92111 | R14: 105.96774 | S14: 106.92882 | T14: 106.59736 | U14: 106.32645 | V14: 107.21366 | W14: 106.62062 | X14: 106.77309 | Y14: 106.57263 | Z14: 107.0816 | AA14: 107.57271 | AC14: 106.79249 | AD14: 107.54973 | AE14: 109.18672 | AF14: 109.79135 | AG14: 110.07431 | AI14: 107.30618 | AJ14: 108.60846 | AM14: 111.17202 | AO14: 111.64399 | AP14: 108.67998 | AQ14: 113.21426 | AR14: 115.89082 | AS14: 116.5583 | AT14: 116.74934 | AU14: 116.87798 | AV14: 114.37532 | AW14: 115.44609 | AX14: 114.58078 | AY14: 116.18785 | AZ14: 117.23631 | BA14: 118.32013 | BB14: 118.29331 | BC14: 118.1282 | BD14: 117.37283 | BE14: 116.43644 | BF14: 114.42135 | BG14: 113.87352 | BH14: 112.93665 | BI14: 111.65465 | BJ14: 109.87967 | BK14: 109.30546 | BL14: 109.33822 | BM14: 108.50462 | BN14: 108.13962 | BO14: 106.75983 | BP14: 102.53524
A15: Armenia | B15: ARM | C15: School enrollment, primary (% gross) | D15: SE.PRM.ENRR | AJ15: 105.59847 | AK15: 97.804657 | AL15: 97.222939 | AM15: 87.24118 | AN15: 81.290977 | AO15: 81.190826 | AP15: 110.73694 | AQ15: 110.95382 | AR15: 117.94826 | AS15: 90.63472 | AT15: 100.95687 | AU15: 100.27549 | AV15: 102.08613 | AW15: 102.15129 | AX15: 100.40918 | AY15: 103.8967 | AZ15: 116.75225 | BA15: 117.70144 | BB15: 113.78272 | BC15: 100.98587 | BD15: 98.334904 | BE15: 97.088127 | BF15: 95.874293 | BG15: 94.41776 | BH15: 93.088059 | BI15: 93.1108 | BJ15: 93.098996 | BK15: 92.134501 | BL15: 92.322824 | BM15: 92.869262 | BN15: 94.63922 | BO15: 96.94543 | BP15: 98.089988 | BQ15: 101.99055
A16: American Samoa | B16: ASM | C16: School enrollment, primary (% gross) | D16: SE.PRM.ENRR | AA16: 98.151649 | AB16: 97.050903 | AC16: 99.848022 | AD16: 102.76733 | AE16: 100.62696 | AF16: 99.124481 | AG16: 99.1493 | AH16: 99.831772 | AI16: 100.71655 | AJ16: 95.050423 | AK16: 89.907631
A17: Antigua and Barbuda | B17: ATG | C17: School enrollment, primary (% gross) | D17: SE.PRM.ENRR | P17: 72.219322 | Q17: 90.211601 | S17: 90.488098 | T17: 91.181129 | U17: 99.867897 | V17: 101.47866 | W17: 99.715347 | X17: 98.882568 | AC17: 137.29366 | AK17: 104.46017 | AN17: 117.20935 | AS17: 135.14215 | AZ17: 116.4469 | BA17: 118.49954 | BB17: 117.93745 | BC17: 120.18368 | BD17: 117.19931 | BE17: 113.61957 | BF17: 113.24592 | BG17: 112.45992 | BH17: 110.39658 | BI17: 107.43266 | BJ17: 109.74291 | BK17: 112.74084 | BL17: 112.84758 | BO17: 121.56321 | BP17: 112.25541
A18: Australia | B18: AUS | C18: School enrollment, primary (% gross) | D18: SE.PRM.ENRR | AS18: 101.58354 | AT18: 101.43941 | AU18: 102.53451 | AV18: 102.85476 | AW18: 103.30206 | AX18: 103.39791 | AY18: 103.56256 | AZ18: 105.42298 | BA18: 105.24463 | BB18: 105.21563 | BC18: 105.4885 | BD18: 105.27488 | BE18: 105.66972 | BF18: 105.80258 | BG18: 105.4616 | BH18: 101.66549 | BI18: 101.18069 | BJ18: 100.63766 | BK18: 100.39871 | BL18: 100.1997 | BM18: 99.901108 | BN18: 99.929153 | BO18: 99.132988 | BP18: 99.365753
A19: Austria | B19: AUT | C19: School enrollment, primary (% gross) | D19: SE.PRM.ENRR | AS19: 101.86939 | AT19: 102.47102 | AU19: 102.81072 | AV19: 102.38444 | AW19: 102.73642 | AX19: 102.08749 | AY19: 102.3109 | AZ19: 102.77166 | BA19: 102.26627 | BB19: 101.36131 | BC19: 100.83554 | BD19: 100.55833 | BE19: 100.33511 | BF19: 100.74608 | BG19: 100.97032 | BH19: 101.10439 | BI19: 100.42808 | BJ19: 101.10457 | BK19: 101.3703 | BL19: 101.77629 | BM19: 101.56085 | BN19: 101.64412 | BO19: 100.77563 | BP19: 100.90287
A20: Azerbaijan | B20: AZE | C20: School enrollment, primary (% gross) | D20: SE.PRM.ENRR | AS20: 97.207489 | AT20: 98.861 | AU20: 98.349426 | AV20: 96.213242 | AW20: 97.26133 | AX20: 95.52697 | AY20: 94.21666 | AZ20: 94.771202 | BA20: 94.072472 | BB20: 95.068573 | BC20: 93.762303 | BD20: 95.573632 | BE20: 97.955307 | BF20: 100.50045 | BG20: 106.05989 | BH20: 106.60149 | BI20: 106.43174 | BJ20: 103.2941 | BK20: 99.722101 | BL20: 97.93535 | BM20: 98.236071 | BN20: 97.7305 | BO20: 99.808298 | BP20: 101.9797 | BQ20: 105.62502
A21: Burundi | B21: BDI | C21: School enrollment, primary (% gross) | D21: SE.PRM.ENRR | P21: 27.90254 | Q21: 26.96557 | R21: 23.57424 | S21: 21.316031 | T21: 21.16864 | U21: 20.641821 | V21: 20.343491 | W21: 21.43202 | X21: 21.410879 | Y21: 22.895029 | Z21: 24.66337 | AA21: 28.43924 | AB21: 34.856499 | AC21: 39.57576 | AD21: 43.895882 | AE21: 47.988079 | AF21: 54.013039 | AG21: 61.161221 | AH21: 62.256371 | AI21: 62.585892 | AJ21: 63.764801 | AK21: 61.289188 | AL21: 61.19281 | AN21: 47.974049 | AO21: 37.982491 | AP21: 39.926231 | AQ21: 48.11208 | AR21: 57.244591 | AS21: 59.236832 | AT21: 61.938251 | AU21: 68.637993 | AV21: 74.176964 | AW21: 79.25544 | AX21: 84.503593 | AY21: 107.59712 | AZ21: 120.35242 | BA21: 123.76885 | BB21: 131.40083 | BC21: 135.15973 | BD21: 135.99222 | BE21: 131.35714 | BF21: 126.11024 | BG21: 121.42411 | BH21: 116.22813 | BI21: 112.48212 | BJ21: 107.55418 | BK21: 104.25645 | BL21: 101.50612 | BM21: 101.66109
A22: Belgium | B22: BEL | C22: School enrollment, primary (% gross) | D22: SE.PRM.ENRR | AS22: 102.90737 | AT22: 103.4267 | AU22: 103.60533 | AV22: 103.77694 | AW22: 103.03942 | AX22: 103.11244 | AY22: 102.7934 | AZ22: 102.4513 | BA22: 102.26573 | BB22: 102.25946 | BC22: 102.23681 | BD22: 101.26989 | BE22: 101.52036 | BF22: 103.19106 | BG22: 103.10487 | BH22: 102.24383 | BI22: 102.05586 | BJ22: 102.75286 | BK22: 102.50037 | BL22: 102.14856 | BM22: 102.06427 | BN22: 101.82114 | BO22: 102.17699 | BP22: 102.10801
A23: Benin | B23: BEN | C23: School enrollment, primary (% gross) | D23: SE.PRM.ENRR | P23: 31.72821 | Q23: 34.342628 | R23: 37.819321 | S23: 36.482059 | T23: 42.47884 | U23: 43.9972 | V23: 46.04414 | W23: 46.982479 | X23: 52.693451 | Y23: 53.96759 | Z23: 55.72691 | AA23: 59.67836 | AB23: 61.373402 | AC23: 59.71888 | AD23: 60.004028 | AE23: 58.058781 | AF23: 58.28299 | AG23: 57.117512 | AH23: 56.424839 | AI23: 47.152031 | AJ23: 53.251968 | AK23: 56.132408 | AL23: 60.965271 | AM23: 61.338799 | AN23: 64.690361 | AO23: 66.987091 | AP23: 70.754082 | AQ23: 73.890343 | AR23: 74.323776 | AS23: 77.292801 | AT23: 84.478554 | AU23: 89.592957 | AV23: 93.192108 | AW23: 96.98716 | AX23: 94.214569 | AY23: 94.332542 | BA23: 106.48396 | BB23: 111.44181 | BC23: 112.79596 | BD23: 114.72313 | BE23: 118.54148 | BF23: 119.38309 | BG23: 119.67539 | BH23: 121.99088 | BI23: 120.30112 | BJ23: 116.29152 | BK23: 111.80507 | BL23: 106.7984 | BM23: 104.03317 | BN23: 105.6313 | BO23: 108.03624
A24: Burkina Faso | B24: BFA | C24: School enrollment, primary (% gross) | D24: SE.PRM.ENRR | P24: 12.48822 | Q24: 12.94747 | R24: 13.24613 | S24: 13.72241 | T24: 14.29943 | U24: 14.71908 | V24: 15.16676 | W24: 15.84464 | X24: 16.488819 | Y24: 17.3951 | Z24: 18.459829 | AA24: 19.912201 | AB24: 21.598339 | AC24: 23.05821 | AD24: 25.18334 | AE24: 27.17099 | AF24: 28.97295 | AG24: 29.39661 | AH24: 30.45841 | AI24: 31.33033 | AJ24: 32.286549 | AK24: 32.84063 | AL24: 33.778542 | AM24: 34.949631 | AN24: 36.812168 | AO24: 38.646118 | AQ24: 40.838322 | AR24: 41.91349 | AS24: 42.817532 | AT24: 44.338139 | AU24: 45.133091 | AV24: 47.53355 | AW24: 52.179089 | AX24: 56.698261 | AY24: 60.375 | AZ24: 65.889183 | BA24: 71.366219 | BB24: 75.785896 | BC24: 76.40553 | BD24: 79.732215 | BE24: 81.981743 | BF24: 83.289089 | BG24: 84.553872 | BH24: 85.148483 | BI24: 87.406526 | BJ24: 89.511833 | BK24: 91.501977 | BL24: 89.786156 | BM24: 87.698847 | BN24: 87.018335 | BO24: 82.256706 | BP24: 72.238595 | BQ24: 77.166593
A25: Bangladesh | B25: BGD | C25: School enrollment, primary (% gross) | D25: SE.PRM.ENRR | O25: 53.323582 | P25: 49.652821 | Q25: 62.130329 | R25: 73.660988 | S25: 71.537407 | T25: 75.48896 | U25: 76.747971 | V25: 71.06517 | W25: 68.655296 | X25: 66.493301 | Y25: 64.193008 | Z25: 62.352791 | AA25: 63.54652 | AB25: 64.535927 | AC25: 63.821449 | AD25: 62.442188 | AE25: 62.466541 | AF25: 61.75058 | AG25: 72.727242 | AH25: 72.561287 | AI25: 75.415443 | AX25: 96.386833 | AY25: 95.876602 | AZ25: 93.662354 | BA25: 90.378227 | BB25: 92.593674 | BC25: 94.776226 | BJ25: 105.12882 | BK25: 107.18996 | BM25: 110.06662 | BN25: 106.33485 | BO25: 107.80207 | BP25: 103.11642 | BQ25: 106.49131
A26: Bulgaria | B26: BGR | C26: School enrollment, primary (% gross) | D26: SE.PRM.ENRR | AS26: 104.70467 | AT26: 105.33926 | AU26: 109.64699 | AV26: 111.69449 | AW26: 111.75123 | AX26: 110.92043 | AY26: 108.82319 | AZ26: 106.10497 | BA26: 104.15756 | BB26: 102.06191 | BC26: 101.40062 | BD26: 101.12027 | BE26: 100.36308 | BF26: 98.791183 | BG26: 99.249611 | BH26: 99.12722 | BI26: 98.077164 | BJ26: 97.594299 | BK26: 96.79232 | BL26: 96.43988 | BM26: 96.543762 | BN26: 95.611099 | BO26: 95.888519 | BP26: 95.423218
A27: Bahrain | B27: BHR | C27: School enrollment, primary (% gross) | D27: SE.PRM.ENRR | P27: 96.471199 | Q27: 96.210739 | R27: 96.36692 | S27: 97.83329 | T27: 102.87098 | U27: 104.93847 | V27: 106.83907 | W27: 107.33798 | X27: 108.09131 | Y27: 105.53797 | Z27: 99.417259 | AA27: 96.484909 | AB27: 95.409721 | AC27: 99.9049 | AD27: 102.244 | AE27: 104.47571 | AF27: 105.05254 | AG27: 106.12534 | AH27: 106.07623 | AI27: 101.89785 | AJ27: 99.724472 | AK27: 93.733223 | AL27: 93.233917 | AM27: 93.227997 | AN27: 94.865173 | AO27: 95.098602 | AP27: 95.909668 | AQ27: 97.351227 | AR27: 99.076782 | AS27: 98.877892 | AT27: 98.286942 | AU27: 96.798347 | AV27: 95.426048 | AW27: 95.149788 | AX27: 95.147751 | AY27: 101.91746 | BD27: 96.119594 | BE27: 101.80322 | BF27: 107.46428 | BG27: 104.36951 | BH27: 100.23702 | BI27: 99.896859 | BJ27: 98.736176 | BK27: 96.838615 | BL27: 96.775414 | BO27: 96.992729 | BP27: 93.899895 | BQ27: 96.875248
A28: Bahamas, The | B28: BHS | C28: School enrollment, primary (% gross) | D28: SE.PRM.ENRR | P28: 105.07012 | Q28: 101.3131 | R28: 94.708221 | S28: 93.848129 | T28: 93.325691 | U28: 92.599518 | V28: 93.005913 | W28: 94.344856 | X28: 94.476631 | Y28: 94.725571 | Z28: 99.101112 | AA28: 100.07654 | AB28: 101.65251 | AC28: 96.566322 | AD28: 105.399 | AE28: 106.31797 | AI28: 107.14542 | AJ28: 106.29224 | AK28: 106.65005 | AL28: 106.74787 | AM28: 102.99951 | AN28: 100.29325 | AO28: 101.44295 | AP28: 96.49572 | AQ28: 94.310677 | AR28: 91.07576 | AU28: 89.142067 | AW28: 96.137962 | AX28: 101.07486 | AY28: 100.1366 | AZ28: 105.79987 | BA28: 107.28162 | BB28: 103.59838 | BC28: 102.48236 | BD28: 110.13575 | BE28: 103.67738 | BF28: 94.640444 | BG28: 94.388211 | BH28: 96.260665 | BI28: 90.411727 | BK28: 88.550077 | BL28: 91.937546 | BN28: 80.523712 | BP28: 78.393193 | BQ28: 92.856648
A29: Bosnia and Herzegovina | B29: BIH | C29: School enrollment, primary (% gross) | D29: SE.PRM.ENRR | AZ29: 108.79678 | BA29: 106.6224 | BB29: 108.09497 | BC29: 88.707077 | BD29: 89.098541 | BE29: 89.209419 | BF29: 89.486961 | BG29: 91.224442 | BH29: 94.695442 | BI29: 96.138634 | BJ29: 98.243599 | BK29: 99.716583 | BL29: 100.92971 | BM29: 100.26393 | BN29: 101.16862 | BO29: 101.60451 | BP29: 101.19488
A30: Belarus | B30: BLR | C30: School enrollment, primary (% gross) | D30: SE.PRM.ENRR | P30: 100.96624 | Q30: 100.88868 | R30: 101.29212 | S30: 100.58491 | T30: 100.61113 | U30: 100.18431 | V30: 100.20007 | W30: 99.57019 | X30: 99.868973 | Y30: 101.33921 | Z30: 103.46784 | AA30: 104.61338 | AB30: 105.93339 | AC30: 107.18002 | AD30: 108.23942 | AE30: 108.55483 | AF30: 94.073471 | AG30: 94.191383 | AH30: 93.62056 | AI30: 92.722763 | AJ30: 94.512932 | AK30: 93.857697 | AL30: 94.065903 | AM30: 95.176392 | AN30: 95.750008 | AO30: 96.649902 | AP30: 99.767418 | AQ30: 103.21465 | AR30: 115.26726 | AS30: 117.42114 | AT30: 117.49288 | AU30: 114.62126 | AV30: 105.36563 | AW30: 103.97982 | AX30: 102.12633 | AY30: 101.28292 | AZ30: 99.837334 | BA30: 99.810188 | BB30: 100.75684 | BC30: 100.77881 | BD30: 100.9274 | BE30: 100.10358 | BF30: 99.402413 | BG30: 98.81963 | BH30: 98.472478 | BI30: 99.41656 | BJ30: 98.991135 | BK30: 98.226083 | BL30: 97.049427 | BM30: 95.525015 | BN30: 95.526644 | BO30: 95.430715 | BP30: 95.218363 | BQ30: 96.822403
A31: Belize | B31: BLZ | C31: School enrollment, primary (% gross) | D31: SE.PRM.ENRR | P31: 104.91077 | Q31: 103.32143 | R31: 104.14122 | S31: 105.60199 | U31: 109.34706 | V31: 114.56327 | W31: 118.8495 | Y31: 124.71535 | Z31: 122.21396 | AA31: 119.09053 | AB31: 115.42273 | AC31: 116.01378 | AD31: 112.64811 | AE31: 106.14906 | AF31: 107.26997 | AG31: 107.739 | AH31: 108.36321 | AI31: 111.60569 | AJ31: 114.84361 | AK31: 115.69354 | AL31: 117.5871 | AM31: 119.99645 | AN31: 120.45071 | AO31: 121.86209 | AP31: 118.85589 | AR31: 116.88449 | AS31: 117.03468 | AT31: 117.08415 | AU31: 113.59685 | AV31: 118.81106 | AW31: 120.60257 | AX31: 120.29735 | AY31: 119.86639 | AZ31: 117.77334 | BA31: 115.30393 | BB31: 114.54534 | BC31: 112.94648 | BD31: 112.27592 | BE31: 115.22258 | BF31: 113.52408 | BG31: 112.82886 | BH31: 113.60255 | BI31: 116.08402 | BJ31: 115.62998 | BK31: 114.90527 | BL31: 114.45835 | BM31: 112.25143 | BN31: 107.33727 | BO31: 101.53137 | BP31: 97.787446 | BQ31: 96.481925
A32: Bermuda | B32: BMU | C32: School enrollment, primary (% gross) | D32: SE.PRM.ENRR | P32: 105.43966 | Q32: 103.63734 | R32: 100.99659 | S32: 100.57391 | T32: 99.697411 | U32: 101.64228 | V32: 103.26308 | W32: 104.76345 | X32: 99.300346 | Y32: 101.76811 | Z32: 102.31034 | AA32: 103.01279 | AB32: 102.80708 | AC32: 101.11538 | AD32: 101.12402 | AN32: 107.69509 | AP32: 120.33136 | AT32: 103.5498 | AU32: 102.93501 | AV32: 103.23741 | AW32: 102.27514 | AX32: 100.93299 | AY32: 99.383904 | BC32: 106.17137 | BD32: 103.87097 | BE32: 101.2488 | BF32: 99.565224 | BG32: 100.56414 | BH32: 102.67393 | BP32: 92.85125
A33: Bolivia | B33: BOL | C33: School enrollment, primary (% gross) | D33: SE.PRM.ENRR | AS33: 119.13207 | AT33: 118.06078 | AU33: 118.54347 | AV33: 116.67719 | AW33: 115.95581 | AX33: 115.19937 | AY33: 113.56164 | AZ33: 112.76772 | BA33: 111.65006 | BB33: 108.03124 | BC33: 104.39637 | BD33: 100.92185 | BE33: 98.312925 | BF33: 96.890474 | BG33: 95.46547 | BH33: 95.096194 | BI33: 95.538766 | BJ33: 96.447504 | BK33: 97.122722 | BL33: 97.671474 | BM33: 98.236949 | BN33: 98.469423 | BO33: 99.196088 | BP33: 98.572689
A34: Brazil | B34: BRA | C34: School enrollment, primary (% gross) | D34: SE.PRM.ENRR | BE34: 104.78223 | BF34: 109.94514 | BG34: 110.31647 | BH34: 109.15219 | BI34: 108.75784 | BJ34: 109.80851 | BK34: 108.62329 | BL34: 107.40748 | BM34: 105.4982 | BN34: 103.47168 | BO34: 103.97032
A35: Barbados | B35: BRB | C35: School enrollment, primary (% gross) | D35: SE.PRM.ENRR | P35: 104.10206 | Q35: 101.11129 | R35: 99.714813 | S35: 94.144913 | T35: 96.568703 | U35: 96.202682 | V35: 102.05375 | W35: 106.0725 | X35: 108.54916 | Y35: 101.67295 | Z35: 104.03487 | AA35: 105.29779 | AB35: 107.58564 | AC35: 114.92154 | AD35: 115.78563 | AH35: 117.50407 | AI35: 112.13527 | AK35: 106.88314 | AR35: 103.17533 | AS35: 102.61624 | AT35: 104.4226 | AU35: 103.54535 | AV35: 104.48761 | AW35: 102.36578 | AX35: 101.59361 | AY35: 101.27604 | AZ35: 100.21299 | BA35: 100.4705 | BB35: 99.802391 | BC35: 100.02649 | BD35: 100.60788 | BG35: 96.433452 | BH35: 95.405183 | BI35: 95.319325 | BJ35: 94.366002 | BK35: 94.472221 | BL35: 94.756144 | BM35: 94.513483 | BN35: 92.770903 | BO35: 90.187532 | BP35: 88.007569 | BQ35: 83.937024
A36: Brunei Darussalam | B36: BRN | C36: School enrollment, primary (% gross) | D36: SE.PRM.ENRR | O36: 121.09825 | P36: 129.26427 | Q36: 131.94438 | R36: 129.27238 | S36: 126.88594 | T36: 122.56371 | U36: 123.97539 | V36: 127.77072 | W36: 128.99236 | X36: 114.10818 | Y36: 113.63823 | Z36: 114.92164 | AA36: 111.80435 | AB36: 113.70134 | AC36: 117.11015 | AD36: 117.04488 | AE36: 122.95289 | AF36: 121.58926 | AG36: 123.29821 | AH36: 125.86278 | AJ36: 116.41947 | AK36: 114.44106 | AL36: 115.30526 | AM36: 115.40352 | AN36: 113.28749 | AO36: 111.85438 | AP36: 110.2139 | AQ36: 113.10862 | AR36: 113.26215 | AS36: 112.03788 | AT36: 110.13542 | AU36: 112.11531 | AV36: 116.92627 | AW36: 119.10534 | AX36: 119.84476 | AY36: 121.50597 | AZ36: 122.32126 | BA36: 116.78313 | BB36: 112.53243 | BC36: 108.70581 | BD36: 104.83089 | BE36: 103.31054 | BF36: 103.89514 | BG36: 103.84771 | BH36: 104.18579 | BI36: 105.72638 | BJ36: 104.56705 | BK36: 104.18 | BL36: 103.03301 | BM36: 102.70963 | BN36: 101.38793 | BO36: 99.134913 | BP36: 96.929219
A37: Bhutan | B37: BTN | C37: School enrollment, primary (% gross) | D37: SE.PRM.ENRR | O37: 19.81324 | P37: 19.724569 | Q37: 21.125071 | S37: 24.19812 | U37: 29.1166 | V37: 31.609091 | W37: 31.65794 | X37: 35.20871 | Y37: 44.750938 | Z37: 49.71954 | AA37: 51.96804 | AB37: 55.396809 | AC37: 57.145988 | AD37: 56.505718 | AE37: 51.898811 | AF37: 52.609829 | AG37: 54.16198 | AJ37: 46.436699 | AK37: 45.327579 | AL37: 54.506611 | AM37: 57.220531 | AN37: 62.32299 | AO37: 68.279449 | AP37: 71.668808 | AQ37: 73.822731 | AR37: 75.681221 | AS37: 77.863182 | AT37: 79.749008 | AU37: 81.868843 | AV37: 84.878433 | AW37: 88.83564 | AX37: 92.443398 | AY37: 97.06134 | AZ37: 101.10329 | BA37: 104.53305 | BB37: 109.00988 | BC37: 111.97585 | BD37: 113.56677 | BE37: 113.01961 | BF37: 106.84125 | BG37: 104.71958 | BH37: 103.0995 | BI37: 101.32402 | BJ37: 99.744772 | BK37: 99.306025 | BL37: 97.989927 | BM37: 103.82601 | BN37: 105.46105 | BO37: 105.26615 | BP37: 106.6874 | BQ37: 114.88112
A38: Botswana | B38: BWA | C38: School enrollment, primary (% gross) | D38: SE.PRM.ENRR | O38: 68.610298 | P38: 64.043167 | Q38: 64.674583 | R38: 70.551872 | S38: 73.8041 | T38: 79.891869 | U38: 83.085571 | V38: 87.399651 | W38: 89.1987 | X38: 91.663551 | Y38: 96.254822 | Z38: 100.53057 | AA38: 101.36552 | AB38: 103.1658 | AC38: 104.72106 | AD38: 107.17562 | AE38: 107.8474 | AF38: 108.05284 | AG38: 108.38635 | AH38: 110.05506 | AI38: 109.42001 | AJ38: 111.72171 | AK38: 109.23182 | AL38: 107.7725 | AM38: 107.28808 | AN38: 106.1337 | AO38: 106.94653 | AP38: 107.54993 | AQ38: 106.83962 | AR38: 107.01438 | AS38: 107.46958 | AT38: 108.97391 | AU38: 109.58321 | AV38: 110.27052 | AW38: 110.61521 | AX38: 111.46208 | AY38: 112.33057 | AZ38: 111.43966 | BA38: 110.97836 | BB38: 111.21366 | BE38: 107.41198 | BF38: 105.31556 | BG38: 101.61661 | BH38: 101.62335 | BN38: 104.61998 | BO38: 109.27326
A39: Central African Republic | B39: CAF | C39: School enrollment, primary (% gross) | D39: SE.PRM.ENRR | P39: 53.77951 | Q39: 52.870972 | R39: 56.12878 | S39: 56.41396 | T39: 58.968601 | U39: 58.724998 | V39: 61.303452 | W39: 61.659821 | X39: 61.695389 | Y39: 62.12616 | Z39: 62.955429 | AA39: 66.819687 | AB39: 70.024231 | AC39: 75.164032 | AD39: 78.857872 | AE39: 78.170891 | AF39: 67.70253 | AG39: 68.614754 | AH39: 68.738358 | AI39: 71.357773 | AJ39: 64.965141 | AK39: 56.024818 | AT39: 68.312767 | AU39: 60.431149 | AV39: 59.68718 | AW39: 51.28706 | AX39: 57.085091 | AY39: 56.701031 | AZ39: 65.553459 | BA39: 75.850349 | BB39: 77.429916 | BC39: 81.278954 | BD39: 81.350403 | BE39: 81.931503 | BI39: 96.812599
A40: Canada | B40: CAN | C40: School enrollment, primary (% gross) | D40: SE.PRM.ENRR | AS40: 99.417763 | AW40: 99.440742 | AX40: 98.598061 | AY40: 99.769531 | AZ40: 99.541481 | BA40: 98.608093 | BB40: 99.607338 | BC40: 99.134369 | BD40: 98.562599 | BE40: 99.490753 | BF40: 99.38678 | BG40: 99.525291 | BH40: 99.86026 | BI40: 98.550041 | BJ40: 98.63224 | BK40: 98.661781 | BL40: 97.187553 | BM40: 96.908974 | BN40: 95.229622 | BO40: 94.74498 | BP40: 94.952339
A41: Central Europe and the Baltics | B41: CEB | C41: School enrollment, primary (% gross) | D41: SE.PRM.ENRR | AR41: 105.80946 | AS41: 101.96642 | AT41: 102.44714 | AU41: 102.62234 | AV41: 102.35455 | AW41: 102.43007 | AX41: 101.76203 | AY41: 101.20799 | AZ41: 100.40537 | BA41: 99.522758 | BB41: 99.586281 | BC41: 99.603477 | BD41: 99.444283 | BE41: 99.617432 | BF41: 98.521156 | BG41: 97.75206 | BH41: 96.900223 | BI41: 96.173637 | BJ41: 95.955978 | BK41: 95.326233 | BL41: 95.89537 | BM41: 91.684464 | BN41: 96.93364 | BO41: 97.046539 | BP41: 98.630661 | BQ41: 98.630653
...
